Workbook

Sheet Skill
A1: id | C1: 招式 | D1: 行动决定后效果参数 | F1: 释放成功效果参数 | I1: 产生交锋效果参数 | K1: 行动后效果参数 | M1: 其他效果参数 | O1: 职能限制 | P1: 技巧点 | R1: 按键 | S1: 可选目标 | T1: 刚炁消耗 | U1: 玄炁消耗 | V1: 派系 | X1: 特效资源 | Y1: 移动类 | Z1: 是否需要目标 | AA1: 能否习得 | AB1: 招式动作
A2: Id | B2: #招式名 | C2: Move | D2: ActionParams | E2: #效果：行动决定后 | F2: ReleaseParams | G2: #效果：行动时 | H2: #效果：释放成功 | I2: CrossSwordsParams | J2: #效果：产生交锋 | K2: FinishParams | L2: #效果：行动后 | M2: OtherParams | N2: #效果：其他 | O2: ProfessionRestriction | Q2: #按键 | R2: Key | S2: Object | T2: GangQiExpend | U2: XuanQiExpend | V2: Sect | W2: #派系 | Z2: ReleaseTargetRequirements | AA2: learnRestriction
A3: int32 | C3: int32 | D3: string | F3: string | I3: string | K3: string | M3: string | O3: int32 | P3: int32 | R3: string | S3: int32 | T3: int32 | U3: int32 | V3: string
A4: 11001 | B4: 快速防守 | C4: 1 | E4: 行动的前2息内即将受到攻击将立即执行本次行动 | G4: 行动期间破与防翻倍，本次行动不会被破招 | J4: 若与杀式交锋则敌手因招式效果获得的炁-100 | L4: 获得1个随机的键 | O4: 1 | P4: 3 | Q4: ↓↓ | R4: {=_xlfn.TEXTJOIN(",",TRUE,MID(SUBSTITUTE(SUBSTITUTE(SUBSTITUTE(SUBSTITUTE($Q4,"↑","1"),"↓","2"),"←","3"),"→","4"),ROW(INDIRECT("1:"&LEN($Q4))),1))} -> 2,2 | S4: 1 | T4: / | U4: / | V4: 20202 | W4: 市井拳脚 | Y4: 2 | Z4: 0 | AA4: 1
A5: 11002 | B5: 起势 | C5: 1 | G5: 获得3个随机的键 | H5: 补充随机的键到达持有上限 | L5: 获得1个随机的键 | O5: 1 | P5: 7 | Q5: ←← | R5: {=_xlfn.TEXTJOIN(",",TRUE,MID(SUBSTITUTE(SUBSTITUTE(SUBSTITUTE(SUBSTITUTE($Q5,"↑","1"),"↓","2"),"←","3"),"→","4"),ROW(INDIRECT("1:"&LEN($Q5))),1))} -> 3,3 | S5: 1 | T5: 8 | U5: 8 | V5: 20301 | W5: 三流散功 | Y5: 2 | Z5: 0 | AA5: 1
A6: 11003 | B6: 借力 | C6: 1 | G6: 行动期间破与防翻倍，本次行动不会被破招 | J6: 获得对方招式构成相同的键 | O6: 1 | P6: 3 | Q6: ↓← | R6: {=_xlfn.TEXTJOIN(",",TRUE,MID(SUBSTITUTE(SUBSTITUTE(SUBSTITUTE(SUBSTITUTE($Q6,"↑","1"),"↓","2"),"←","3"),"→","4"),ROW(INDIRECT("1:"&LEN($Q6))),1))} -> 2,3 | S6: 1 | T6: / | U6: / | V6: 20201 | W6: 常功 | Y6: 2 | Z6: 0 | AA6: 1
A7: 11004 | B7: 汲苦 | C7: 1 | G7: 行动期间受到直接伤害时恢复伤害量30%的体，本次行动不会被破招 | J7: 若互为目标则敌手因招式效果获得的炁-100 | L7: 行动期间若受到过直接伤害则刚炁+15 | O7: 1 | P7: 4 | Q7: ↓↓↑ | R7: {=_xlfn.TEXTJOIN(",",TRUE,MID(SUBSTITUTE(SUBSTITUTE(SUBSTITUTE(SUBSTITUTE($Q7,"↑","1"),"↓","2"),"←","3"),"→","4"),ROW(INDIRECT("1:"&LEN($Q7))),1))} -> 2,2,1 | S7: 1 | T7: / | U7: / | V7: 20404 | W7: 业生寺 | Y7: 2 | Z7: 0 | AA7: 1
A8: 11005 | B8: 招架 | C8: 1 | G8: 行动期间破与防翻倍，本次行动不会被破招且持续到下个回合开始或下一次行动 | J8: 若与杀式交锋则敌手因招式效果获得的炁-100 | L8: 获得1个随机的键 | O8: 1 | P8: 2 | Q8: ↓↓← | R8: {=_xlfn.TEXTJOIN(",",TRUE,MID(SUBSTITUTE(SUBSTITUTE(SUBSTITUTE(SUBSTITUTE($Q8,"↑","1"),"↓","2"),"←","3"),"→","4"),ROW(INDIRECT("1:"&LEN($Q8))),1))} -> 2,2,3 | S8: 1 | T8: / | U8: / | V8: 20101 | W8: 基本功 | Y8: 2 | Z8: 0 | AA8: 1
A9: 11006 | B9: 外炁屏障 | C9: 1 | E9: 招式的招式的刚炁消耗转为当前50%，至多50 | H9: 获得80%力的护体 | L9: 玄炁+10，下个回合开始获得本回合结束时等量的护体 | N9: 炁拶 | O9: 1 | P9: 2 | Q9: ↑→↓ | R9: {=_xlfn.TEXTJOIN(",",TRUE,MID(SUBSTITUTE(SUBSTITUTE(SUBSTITUTE(SUBSTITUTE($Q9,"↑","1"),"↓","2"),"←","3"),"→","4"),ROW(INDIRECT("1:"&LEN($Q9))),1))} -> 1,4,2 | S9: 1 | T9: 25 | U9: / | V9: 20201 | W9: 常功 | Y9: 2 | Z9: 0 | AA9: 1
A10: 11007 | B10: 风传 | C10: 1 | E10: 行动加快2息 | H10: 指定友方获得2层迅速，清除目标的缓速状态 | L10: 玄炁+20，双方获得2个随机的键 | O10: 6 | P10: 10 | Q10: ↓←←↓ | R10: {=_xlfn.TEXTJOIN(",",TRUE,MID(SUBSTITUTE(SUBSTITUTE(SUBSTITUTE(SUBSTITUTE($Q10,"↑","1"),"↓","2"),"←","3"),"→","4"),ROW(INDIRECT("1:"&LEN($Q10))),1))} -> 2,3,3,2 | S10: 2 | T10: 20 | U10: / | V10: 20303 | W10: 羽楼 | Y10: 1 | Z10: 1 | AA10: 1
A11: 11008 | B11: 临阵之志 | C11: 1 | E11: 行动加快1息 | H11: 获得一层反击 | L11: 在3息内反击不会低于一层 | O11: 4 | P11: 8 | Q11: ↓↓→↑ | R11: {=_xlfn.TEXTJOIN(",",TRUE,MID(SUBSTITUTE(SUBSTITUTE(SUBSTITUTE(SUBSTITUTE($Q11,"↑","1"),"↓","2"),"←","3"),"→","4"),ROW(INDIRECT("1:"&LEN($Q11))),1))} -> 2,2,4,1 | S11: 1 | T11: 20 | U11: / | V11: 20305 | W11: 忱武堂 | Y11: 2 | Z11: 0 | AA11: 1
A12: 11009 | B12: 聚炁 | C12: 1 | H12: 刚炁+15，玄炁+15 | O12: 1 | P12: 5 | Q12: ↑↑ | R12: {=_xlfn.TEXTJOIN(",",TRUE,MID(SUBSTITUTE(SUBSTITUTE(SUBSTITUTE(SUBSTITUTE($Q12,"↑","1"),"↓","2"),"←","3"),"→","4"),ROW(INDIRECT("1:"&LEN($Q12))),1))} -> 1,1 | S12: 1 | T12: / | U12: / | V12: 20101 | W12: 基本功 | Y12: 2 | Z12: 0 | AA12: 1
A13: 11010 | B13: 运玄流 | C13: 1 | E13: 行动延迟2息 | H13: 玄炁+50 | L13: 每次使用后该招式减少2刚炁消耗减少5玄炁增加 | O13: 1 | P13: 8 | Q13: ↑↑← | R13: {=_xlfn.TEXTJOIN(",",TRUE,MID(SUBSTITUTE(SUBSTITUTE(SUBSTITUTE(SUBSTITUTE($Q13,"↑","1"),"↓","2"),"←","3"),"→","4"),ROW(INDIRECT("1:"&LEN($Q13))),1))} -> 1,1,3 | S13: 1 | T13: 20 | U13: / | V13: 20201 | W13: 常功 | Y13: 2 | Z13: 0 | AA13: 1
A14: 11011 | B14: 运刚流 | C14: 1 | E14: 行动延迟2息 | H14: 刚炁+50 | L14: 每次使用后该招式减少2玄炁消耗减少5刚炁增加 | O14: 1 | P14: 8 | Q14: ↑↑→ | R14: {=_xlfn.TEXTJOIN(",",TRUE,MID(SUBSTITUTE(SUBSTITUTE(SUBSTITUTE(SUBSTITUTE($Q14,"↑","1"),"↓","2"),"←","3"),"→","4"),ROW(INDIRECT("1:"&LEN($Q14))),1))} -> 1,1,4 | S14: 1 | T14: / | U14: 20 | V14: 20201 | W14: 常功 | Y14: 2 | Z14: 0 | AA14: 1
A15: 11012 | B15: 铩血功 | C15: 1 | H15: 获得100%力的血炁甲状态层数，玄炁+5 | L15: 下次行动前受到伤害后减少等量体获得等量血炁甲层数 | O15: 2 | P15: 9 | Q15: ↑→→↓ | R15: {=_xlfn.TEXTJOIN(",",TRUE,MID(SUBSTITUTE(SUBSTITUTE(SUBSTITUTE(SUBSTITUTE($Q15,"↑","1"),"↓","2"),"←","3"),"→","4"),ROW(INDIRECT("1:"&LEN($Q15))),1))} -> 1,4,4,2 | S15: 1 | T15: 30 | U15: / | V15: 20306 | W15: 血霞秘功 | Y15: 2 | Z15: 0 | AA15: 1
A16: 11013 | B16: 快服 | C16: 1 | E16: 选择消耗品使用 | H16: 消耗物品产生对应效果 | O16: 1 | P16: 0 | Q16: ← | R16: {=_xlfn.TEXTJOIN(",",TRUE,MID(SUBSTITUTE(SUBSTITUTE(SUBSTITUTE(SUBSTITUTE($Q16,"↑","1"),"↓","2"),"←","3"),"→","4"),ROW(INDIRECT("1:"&LEN($Q16))),1))} -> 3 | S16: 1 | T16: / | U16: / | V16: 20101 | W16: 基本功 | Y16: 2 | Z16: 0 | AA16: 1
A17: 11014 | B17: 披茧功 | C17: 1 | G17: 刚炁至少50则本次行动不会被破招 | H17: 将自身至多2个随机异常状态转为等量随机1层增益状态（迅速/刚聚/力增/武增） | L17: 获得6个不同的键，获得2层心眼 | O17: 4 | P17: 5 | Q17: ←↑← | R17: {=_xlfn.TEXTJOIN(",",TRUE,MID(SUBSTITUTE(SUBSTITUTE(SUBSTITUTE(SUBSTITUTE($Q17,"↑","1"),"↓","2"),"←","3"),"→","4"),ROW(INDIRECT("1:"&LEN($Q17))),1))} -> 3,1,3 | S17: 1 | T17: / | U17: 25 | V17: 20404 | W17: 业生寺 | Y17: 2 | Z17: 0 | AA17: 1
A18: 11015 | B18: 汇力诀 | C18: 1 | E18: 获得3层心眼状态 | H18: 刚炁+60 | L18: 获得1层武增和2层力增 | O18: 1 | P18: 5 | Q18: ↑←↑ | R18: {=_xlfn.TEXTJOIN(",",TRUE,MID(SUBSTITUTE(SUBSTITUTE(SUBSTITUTE(SUBSTITUTE($Q18,"↑","1"),"↓","2"),"←","3"),"→","4"),ROW(INDIRECT("1:"&LEN($Q18))),1))} -> 1,3,1 | S18: 1 | T18: 45 | U18: / | V18: 20305 | W18: 忱武堂 | Y18: 2 | Z18: 0 | AA18: 1
A19: 11016 | B19: 玄龙灌体 | C19: 1 | G19: 键至少5则本次行动不会被破招 | H19: 获得2层武增状态和3层力增状态和4层刚聚状态 | L19: 获得5个随机的键 | O19: 2 | P19: 4 | Q19: ↑↓ | R19: {=_xlfn.TEXTJOIN(",",TRUE,MID(SUBSTITUTE(SUBSTITUTE(SUBSTITUTE(SUBSTITUTE($Q19,"↑","1"),"↓","2"),"←","3"),"→","4"),ROW(INDIRECT("1:"&LEN($Q19))),1))} -> 1,2 | S19: 1 | T19: / | U19: 35 | V19: 20305 | W19: 忱武堂 | Y19: 2 | Z19: 0 | AA19: 1
A20: 11017 | B20: 调步 | C20: 1 | H20: 获得2层玄聚状态 | L20: 消耗全部的键获得（等量+4）随机的键，获得1次行动次数 | O20: 1 | P20: 3 | Q20: ↓←→↑ | R20: {=_xlfn.TEXTJOIN(",",TRUE,MID(SUBSTITUTE(SUBSTITUTE(SUBSTITUTE(SUBSTITUTE($Q20,"↑","1"),"↓","2"),"←","3"),"→","4"),ROW(INDIRECT("1:"&LEN($Q20))),1))} -> 2,3,4,1 | S20: 1 | T20: 30 | U20: / | V20: 20201 | W20: 常功 | Y20: 2 | Z20: 0 | AA20: 1
A21: 11018 | B21: 生生不息 | C21: 1 | G21: 本次行动不会被未带有←类留劲状态的敌手破招 | H21: 玄炁上限+40% | L21: 玄炁+40% | O21: 800002|800003|800004|800005|800006 | P21: 999 | Q21: ↑↑→↓ | R21: {=_xlfn.TEXTJOIN(",",TRUE,MID(SUBSTITUTE(SUBSTITUTE(SUBSTITUTE(SUBSTITUTE($Q21,"↑","1"),"↓","2"),"←","3"),"→","4"),ROW(INDIRECT("1:"&LEN($Q21))),1))} -> 1,1,4,2 | S21: 1 | T21: / | U21: / | V21: 20001 | W21: 无 | Y21: 2 | Z21: 0 | AA21: 0
A22: 11019 | B22: 生生不息 | C22: 1 | G22: 本次行动不会被未带有←类留劲状态的敌手破招 | H22: 玄炁上限+55% | L22: 玄炁+55% | O22: 800002|800003|800004|800005|800006 | P22: 999 | Q22: ↑↑→↓ | R22: {=_xlfn.TEXTJOIN(",",TRUE,MID(SUBSTITUTE(SUBSTITUTE(SUBSTITUTE(SUBSTITUTE($Q22,"↑","1"),"↓","2"),"←","3"),"→","4"),ROW(INDIRECT("1:"&LEN($Q22))),1))} -> 1,1,4,2 | S22: 1 | T22: / | U22: / | V22: 20001 | W22: 无 | Y22: 2 | Z22: 0 | AA22: 0
A23: 11020 | B23: 灵归 | C23: 1 | E23: 随机获得5个键 | H23: 将持有键替换为不同的键各2个 | L23: 玄炁+75% | O23: 800002|800003|800004|800005|800006 | P23: 999 | Q23: ↓↑ | R23: {=_xlfn.TEXTJOIN(",",TRUE,MID(SUBSTITUTE(SUBSTITUTE(SUBSTITUTE(SUBSTITUTE($Q23,"↑","1"),"↓","2"),"←","3"),"→","4"),ROW(INDIRECT("1:"&LEN($Q23))),1))} -> 2,1 | S23: 1 | T23: / | U23: 5000 | V23: 20001 | W23: 无 | Y23: 2 | Z23: 0 | AA23: 0
A24: 11021 | B24: 观 | C24: 1 | E24: 行动延迟1息 | H24: 获得3层心眼状态，获得1次行动次数 | O24: 5 | P24: 3 | Q24: →↓ | R24: {=_xlfn.TEXTJOIN(",",TRUE,MID(SUBSTITUTE(SUBSTITUTE(SUBSTITUTE(SUBSTITUTE($Q24,"↑","1"),"↓","2"),"←","3"),"→","4"),ROW(INDIRECT("1:"&LEN($Q24))),1))} -> 4,2 | S24: 1 | T24: / | U24: 20 | V24: 20301 | W24: 三流散功 | Y24: 2 | Z24: 0 | AA24: 1
A25: 11022 | B25: 灵归 | C25: 1 | E25: 随机获得5个键 | H25: 将持有键替换为不同的键各2个 | L25: 玄炁+75%，若被破招则下次使用该招式不会被破招 | O25: 800002|800003|800004|800005|800006 | P25: 999 | Q25: ↓↑ | R25: {=_xlfn.TEXTJOIN(",",TRUE,MID(SUBSTITUTE(SUBSTITUTE(SUBSTITUTE(SUBSTITUTE($Q25,"↑","1"),"↓","2"),"←","3"),"→","4"),ROW(INDIRECT("1:"&LEN($Q25))),1))} -> 2,1 | S25: 1 | T25: / | U25: 5000 | V25: 20001 | W25: 无 | Y25: 2 | Z25: 0 | AA25: 0
A26: 11023 | B26: 铁筋功 | C26: 1 | G26: 行动期间破与防翻倍，本次行动不会被破招且持续到下个回合开始 | J26: 施加3层力衰状态 | L26: 获得1个随机的键 | O26: 1 | P26: 4 | Q26: ↓↓←→ | R26: {=_xlfn.TEXTJOIN(",",TRUE,MID(SUBSTITUTE(SUBSTITUTE(SUBSTITUTE(SUBSTITUTE($Q26,"↑","1"),"↓","2"),"←","3"),"→","4"),ROW(INDIRECT("1:"&LEN($Q26))),1))} -> 2,2,3,4 | S26: 1 | T26: / | U26: / | V26: 20301 | W26: 三流散功 | Y26: 2 | Z26: 0 | AA26: 1
A27: 11024 | B27: 焚羽凌霄 | C27: 1 | G27: 获得10层缓速和10层迅速和5层玄聚和5层玄屏和5层刚聚和5层刚屏 | H27: 获得5层术衰状态和5层术增状态和5层技增状态和5层技衰状态和5层力衰状态和5层力增状态和5层武增状态和5层武衰状态 | L27: 将玄炁和刚炁的持有量变为50，获得5个随机的键 | O27: 2 | P27: 12 | Q27: ↑→↓← | R27: {=_xlfn.TEXTJOIN(",",TRUE,MID(SUBSTITUTE(SUBSTITUTE(SUBSTITUTE(SUBSTITUTE($Q27,"↑","1"),"↓","2"),"←","3"),"→","4"),ROW(INDIRECT("1:"&LEN($Q27))),1))} -> 1,4,2,3 | S27: 1 | T27: / | U27: 80 | V27: 20702 | W27: 四象形意 | Y27: 2 | Z27: 0 | AA27: 1
A28: 11025 | B28: 化蜕虫 | C28: 1 | G28: 获得10层缓速和10层迅速 | H28: 获得5层术衰状态和5层术增和5层技增和5层技衰 | L28: 获得5个随机的键 | O28: 2 | P28: 10 | Q28: ↑→↓← | R28: {=_xlfn.TEXTJOIN(",",TRUE,MID(SUBSTITUTE(SUBSTITUTE(SUBSTITUTE(SUBSTITUTE($Q28,"↑","1"),"↓","2"),"←","3"),"→","4"),ROW(INDIRECT("1:"&LEN($Q28))),1))} -> 1,4,2,3 | S28: 1 | T28: / | U28: 40 | V28: 20301 | W28: 三流散功 | Y28: 2 | Z28: 0 | AA28: 1
A29: 11026 | B29: 鸩姿 | C29: 1 | G29: 补充随机的键到达持有上限 | H29: 获得1次行动次数，下回合开始消耗全部键 | O29: 5 | P29: 5 | Q29: ↓←← | R29: {=_xlfn.TEXTJOIN(",",TRUE,MID(SUBSTITUTE(SUBSTITUTE(SUBSTITUTE(SUBSTITUTE($Q29,"↑","1"),"↓","2"),"←","3"),"→","4"),ROW(INDIRECT("1:"&LEN($Q29))),1))} -> 2,3,3 | S29: 1 | T29: 20 | U29: / | V29: 20303 | W29: 羽楼 | Y29: 2 | Z29: 0 | AA29: 1
A30: 11027 | B30: 静待流觞 | C30: 1 | G30: 行动期间防翻倍，本次行动不会被武杀式破招且持续到下个回合开始或下一次行动 | J30: 若与杀式交锋则刚炁+20,若且互为目标则消耗目标20刚炁 | O30: 1 | P30: 3 | Q30: ↓→ | R30: {=_xlfn.TEXTJOIN(",",TRUE,MID(SUBSTITUTE(SUBSTITUTE(SUBSTITUTE(SUBSTITUTE($Q30,"↑","1"),"↓","2"),"←","3"),"→","4"),ROW(INDIRECT("1:"&LEN($Q30))),1))} -> 2,4 | S30: 1 | T30: / | U30: 20 | V30: 20306 | W30: 血霞秘功 | Y30: 2 | Z30: 0 | AA30: 1
A31: 11028 | B31: 逃之夭夭 | C31: 1 | G31: 本次行动不会被破招 | H31: 退出战斗 | N31: 迅速状态超过6时可使用 | O31: 1 | P31: 999 | Q31: ← | R31: {=_xlfn.TEXTJOIN(",",TRUE,MID(SUBSTITUTE(SUBSTITUTE(SUBSTITUTE(SUBSTITUTE($Q31,"↑","1"),"↓","2"),"←","3"),"→","4"),ROW(INDIRECT("1:"&LEN($Q31))),1))} -> 3 | S31: 1 | T31: / | U31: / | V31: 20001 | W31: 无 | Y31: 2 | Z31: 0 | AA31: 0
A32: 11029 | B32: 周旋 | C32: 1 | H32: 获得1层回避 | L32: 获得4个不同的键 | O32: 5 | P32: 3 | Q32: ←←← | R32: {=_xlfn.TEXTJOIN(",",TRUE,MID(SUBSTITUTE(SUBSTITUTE(SUBSTITUTE(SUBSTITUTE($Q32,"↑","1"),"↓","2"),"←","3"),"→","4"),ROW(INDIRECT("1:"&LEN($Q32))),1))} -> 3,3,3 | S32: 1 | T32: / | U32: 25 | V32: 20201 | W32: 常功 | Y32: 2 | Z32: 0 | AA32: 1
A33: 11030 | B33: 遁江 | C33: 1 | E33: 若未成为敌手的行动目标则获得1层匿形状态 | L33: 刚炁+20 | N33: 在水域场景可使用 | O33: 1 | P33: 2 | Q33: ↑↑ | R33: {=_xlfn.TEXTJOIN(",",TRUE,MID(SUBSTITUTE(SUBSTITUTE(SUBSTITUTE(SUBSTITUTE($Q33,"↑","1"),"↓","2"),"←","3"),"→","4"),ROW(INDIRECT("1:"&LEN($Q33))),1))} -> 1,1 | S33: 1 | T33: / | U33: 10 | V33: 20205 | W33: 渔术 | Y33: 2 | Z33: 0 | AA33: 1
A34: 11031 | B34: 好戏开场 | C34: 1 | E34: 本次行动延迟1息 | H34: 下次行动的玄炁消耗减少30 | O34: 1 | P34: 5 | Q34: ↑↓ | R34: {=_xlfn.TEXTJOIN(",",TRUE,MID(SUBSTITUTE(SUBSTITUTE(SUBSTITUTE(SUBSTITUTE($Q34,"↑","1"),"↓","2"),"←","3"),"→","4"),ROW(INDIRECT("1:"&LEN($Q34))),1))} -> 1,2 | S34: 1 | T34: 5 | U34: / | V34: 20203 | W34: 野法乱术 | Y34: 2 | Z34: 0 | AA34: 1
A35: 11032 | B35: 围追堵截 | C35: 1 | G35: 行动期间破与防翻倍，本次行动不会被破招且持续到下个回合开始，目标本次杀式行动的目标转来至自身 | L35: 获得1个随机的键 | O35: 800086|800087|800088|800089|800090|800091|800092 | P35: 7 | Q35: ↓↑↓ | R35: {=_xlfn.TEXTJOIN(",",TRUE,MID(SUBSTITUTE(SUBSTITUTE(SUBSTITUTE(SUBSTITUTE($Q35,"↑","1"),"↓","2"),"←","3"),"→","4"),ROW(INDIRECT("1:"&LEN($Q35))),1))} -> 2,1,2 | S35: 1 | T35: / | U35: / | V35: 20205 | W35: 渔术 | Y35: 2 | Z35: 1 | AA35: 1
A36: 11033 | B36: 妖化 | C36: 1 | H36: 获得2层巧增 | L36: 玄炁+40，下回合猊煞状态不会产生消耗 | N36: 持有猊煞状态可使用 | O36: 1 | P36: 1 | Q36: ↑↑← | R36: {=_xlfn.TEXTJOIN(",",TRUE,MID(SUBSTITUTE(SUBSTITUTE(SUBSTITUTE(SUBSTITUTE($Q36,"↑","1"),"↓","2"),"←","3"),"→","4"),ROW(INDIRECT("1:"&LEN($Q36))),1))} -> 1,1,3 | S36: 1 | T36: 15 | U36: / | V36: 20403 | W36: 猊煞变 | Y36: 2 | Z36: 0 | AA36: 1
A37: 11034 | B37: 叩天门 | C37: 1 | E37: 获得1层烈命状态 | H37: 获得1次行动次数 | O37: 2 | P37: 12 | Q37: ←→↑ | R37: {=_xlfn.TEXTJOIN(",",TRUE,MID(SUBSTITUTE(SUBSTITUTE(SUBSTITUTE(SUBSTITUTE($Q37,"↑","1"),"↓","2"),"←","3"),"→","4"),ROW(INDIRECT("1:"&LEN($Q37))),1))} -> 3,4,1 | S37: 1 | T37: 30 | U37: / | Y37: 2 | Z37: 0 | AA37: 1
A38: 11035 | B38: 暴怒 | C38: 1 | E38: 获得4次破招抵免，本次行动持续到下次行动 | H38: 直到下次行动前速固定为1，若期间未被破招则下次行动释放武杀式：撼地 | L38: 之后再次使用该招式所获得的破招抵免在本次战斗中提升2次 | N38: 剩余行动次数为1时可使用 | O38: 800075|800076|800077 | P38: 999 | R38: {=_xlfn.TEXTJOIN(",",TRUE,MID(SUBSTITUTE(SUBSTITUTE(SUBSTITUTE(SUBSTITUTE($Q38,"↑","1"),"↓","2"),"←","3"),"→","4"),ROW(INDIRECT("1:"&LEN($Q38))),1))} -> #REF! | S38: 1 | V38: 20001 | W38: 无 | Y38: 2 | Z38: 0 | AA38: 0
A39: 11036 | B39: 舔舐伤口 | C39: 1 | H39: 清除自身3个异常状态，若清除数量不超过3个则每少1个给予1层武增1层力增1层巧增 | O39: 800075|800076|800077 | P39: 999 | R39: {=_xlfn.TEXTJOIN(",",TRUE,MID(SUBSTITUTE(SUBSTITUTE(SUBSTITUTE(SUBSTITUTE($Q39,"↑","1"),"↓","2"),"←","3"),"→","4"),ROW(INDIRECT("1:"&LEN($Q39))),1))} -> #REF! | S39: 1 | V39: 20001 | W39: 无 | Y39: 2 | Z39: 0 | AA39: 0
A40: 11037 | B40: 垂身喘息 | C40: 1 | H40: 刚炁+100，随机获得5个键 | J40: 敌手因招式效果获得的炁-100，交锋失败则在下一息重复该招式 | O40: 800075|800076|800077 | P40: 999 | R40: {=_xlfn.TEXTJOIN(",",TRUE,MID(SUBSTITUTE(SUBSTITUTE(SUBSTITUTE(SUBSTITUTE($Q40,"↑","1"),"↓","2"),"←","3"),"→","4"),ROW(INDIRECT("1:"&LEN($Q40))),1))} -> #REF! | S40: 1 | V40: 20001 | W40: 无 | Y40: 2 | Z40: 0 | AA40: 0
...

Sheet 派系强度阶梯
B1: 炁拶 | C1: 非派式 | E1: 派式
A2: 特殊 | C2: 孤支奇功 | D2: =COUNTIF(Skill!V:V,20701) -> 8 | E2: 四象形意（4） | F2: =COUNTIF(Skill!V:V,20702) -> 4 | G2: 金真妙法 | H2: =COUNTIF(Skill!V:V,20402) -> 6 | I2: 蕃寰曲 | J2: =COUNTIF(Skill!V:V,20307) -> 4 | K2: 丹经脉录 | L2: =COUNTIF(Skill!V:V,20705) -> 3
A3: 后期 | C3: 超一流 | D3: =COUNTIF(Skill!V:V,20601) -> 1 | E3: 傀摆戏 | F3: =COUNTIF(Skill!V:V,20602) -> 3 | G3: 墨刀 | H3: =COUNTIF(Skill!V:V,20603) -> 2 | I3: 自如梦 | J3: =COUNTIF(Skill!V:V,20604) -> 8
A4: 中后期 | C4: 一流散功 | D4: =COUNTIF(Skill!V:V,20501) -> 1 | E4: 指爻派 | F4: =COUNTIF(Skill!V:V,20502) -> 14 | G4: 元真门 | H4: =COUNTIF(Skill!V:V,20503) -> 5 | I4: 泊风刀法（1） | J4: =COUNTIF(Skill!V:V,20504) -> 2 | K4: 敷宵宗 | L4: =COUNTIF(Skill!V:V,20505) -> 6 | M4: 雷家功 | N4: =COUNTIF(Skill!V:V,20506) -> 2 | O4: 萨么通幽 | P4: =COUNTIF(Skill!V:V,20507) -> 21 | Q4: 天泪八技（1） | R4: =COUNTIF(Skill!V:V,20508) -> 3
A5: 中期 | C5: 二流散功 | D5: =COUNTIF(Skill!V:V,20401) -> 9 | G5: 猊煞变 | H5: =COUNTIF(Skill!V:V,20403) -> 2 | I5: 业生寺 | J5: =COUNTIF(Skill!V:V,20404) -> 6 | K5: 异道载 | L5: =COUNTIF(Skill!V:V,20405) -> 2 | M5: 第五绝功 | N5: =COUNTIF(Skill!V:V,20406) -> 3 | O5: 幻千笈 | P5: =COUNTIF(Skill!V:V,20407) -> 3 | Q5: 空青阁 | R5: =COUNTIF(Skill!V:V,20408) -> 0 | S5: 天公道 | T5: =COUNTIF(Skill!V:V,20409) -> 2
A6: 前中期 | C6: 三流散功 | D6: =COUNTIF(Skill!V:V,20301) -> 11 | E6: 基础法咒 | F6: =COUNTIF(Skill!V:V,20302) -> 8 | G6: 羽楼 | H6: =COUNTIF(Skill!V:V,20303) -> 8 | I6: 炁卜 | J6: =COUNTIF(Skill!V:V,20304) -> 4 | K6: 忱武堂 | L6: =COUNTIF(Skill!V:V,20305) -> 7 | M6: 血霞秘功◈ | N6: =COUNTIF(Skill!V:V,20306) -> 7
A7: 前期 | C7: 常功 | D7: =COUNTIF(Skill!V:V,20201) -> 18 | E7: 市井拳脚 | F7: =COUNTIF(Skill!V:V,20202) -> 12 | G7: 野法乱术◈ | H7: =COUNTIF(Skill!V:V,20203) -> 8 | I7: 乌仇神功 | J7: =COUNTIF(Skill!V:V,20204) -> 5 | K7: 渔术◈ | L7: =COUNTIF(Skill!V:V,20205) -> 11
A8: 初始 | C8: 基本功 | D8: =COUNTIF(Skill!V:V,20101) -> 18
C9: 无 | D9: =COUNTIF(Skill!V:V,20001) -> 82
G13: 强度模型 | H13: 低 | J13: 中 | L13: 高 | Q13: 键规律 | R13: 包含
G14: 后期 | H14: 125 | J14: 145 | L14: 165 | Q14: 防御类 | R14: ↓
G15: 中后期 | H15: 120 | J15: 140 | L15: 160 | Q15: 恢复炁 | R15: ↑
G16: 中期 | H16: 115 | J16: 135 | L16: 155 | Q16: 加速度 | R16: →
G17: 前中期 | H17: 110 | J17: 130 | L17: 150
G18: 前期 | H18: 105 | J18: 125 | L18: 145
G19: 初始 | H19: 100 | J19: 120 | L19: 140
G21: 消耗 | H21: 10~20 | J21: 30~40 | L21: 45~60

Sheet Sheet2
B3: 技能效果 | C3: 出现 | D3: 设定 | H3: 前期 | I3: 前中期 | J3: 中期 | K3: 中后期 | L3: 后期 | M3: 特殊
A4: 1 | B4: 至少造成x%力/技的伤害时 | C4: 多 | D4: 被回避、护体、防御、更强的杀式交锋等手段反制
A5: 2 | B5: 未产生交锋时生效 | C5: 中 | D5: 偷刀招式，需要掩护或者时机
A6: 3 | B6: 纯粹产生延续收益、恢复战斗资源 | C6: 中 | D6: 易被攻击打断损失收益
A7: 4 | B7: 各种负面效果于招式内占比较大 | C7: 多 | D7: 施加负面，削弱、限制敌手行动
A8: 5 | B8: 威力为主 | C8: 多 | D8: 拼招、造成直接伤害为主
A9: 6 | B9: 削减目标的炁 | C9: 多 | D9: 打断炁消耗与持有炁差距不大时释放的招式、抑制敌手高强招式的使用
A10: 7 | B10: 恢复战斗资源的攻击 | C10: 多 | D10: 被阻止恢复炁的招式克制
F16: 风步移形
F17: 止水折流
F18: 胎光游虚

Sheet Sheet1
A1: id | C1: 招式 | D1: 行动决定后效果参数 | F1: 释放成功效果参数 | H1: 产生交锋效果参数 | J1: 行动后效果参数 | L1: 其他效果参数 | N1: 职能限制 | O1: 技巧点 | Q1: 按键 | R1: 可选目标 | S1: 刚炁消耗 | T1: 玄炁消耗 | U1: 派系 | W1: 特效资源 | X1: 特效产生点 | Y1: 是否需要目标 | Z1: 能否习得
A2: Id | B2: #招式名 | C2: Move | D2: ActionParams | E2: 行动决定后 | F2: ReleaseParams | G2: 释放成功 | H2: CrossSwordsParams | I2: 产生交锋 | J2: FinishParams | K2: 行动后 | L2: OtherParams | M2: #效果：其他 | N2: ProfessionRestriction | P2: #按键 | Q2: Key | R2: Object | S2: GangQiExpend | T2: XuanQiExpend | U2: Sect | V2: #派系 | Y2: ReleaseTargetRequirements | Z2: learnRestriction
A3: int32 | C3: int32 | D3: string | F3: string | H3: string | J3: string | L3: string | N3: int32 | O3: int32 | Q3: string | R3: int32 | S3: int32 | T3: int32 | U3: string
B27: ↑ | C27: {=SUMPRODUCT(LEN(P:P)-LEN(SUBSTITUTE(P:P,"↑","")))} -> 0
B28: ↓ | C28: {=SUMPRODUCT(LEN(P:P)-LEN(SUBSTITUTE(P:P,"↓","")))} -> 0
B29: ← | C29: {=SUMPRODUCT(LEN(P:P)-LEN(SUBSTITUTE(P:P,"←","")))} -> 0
B30: → | C30: {=SUMPRODUCT(LEN(P:P)-LEN(SUBSTITUTE(P:P,"→","")))} -> 0
